[2020-03-05 08:22:42,895] sopel.irc            ERROR    - ERROR received from server: Closing link: (sopel@jlogerqubox.adtran.com) [Quit: Closing]
[2020-03-05 08:26:27,956] sopel.bot            ERROR    - Error in ip setup: Missing required value for ip.GeoIP_db_path
Traceback (most recent call last):
  File "/usr/local/lib/python3.6/dist-packages/sopel/config/types.py", line 57, in __init__
    getattr(self, value)
  File "/usr/local/lib/python3.6/dist-packages/sopel/config/types.py", line 512, in __get__
    this_section = getattr(main_config, instance._section_name)
  File "/usr/local/lib/python3.6/dist-packages/sopel/config/__init__.py", line 292, in __getattr__
    section = self.ConfigSection(name, items, self)  # Return a section
  File "/usr/local/lib/python3.6/dist-packages/sopel/config/__init__.py", line 248, in __init__
    value = item[1].strip()
AttributeError: 'NoneType' object has no attribute 'strip'

During handling of the above exception, another exception occurred:

Traceback (most recent call last):
  File "/usr/local/lib/python3.6/dist-packages/sopel/bot.py", line 213, in setup_plugins
    plugin.setup(self)
  File "/usr/local/lib/python3.6/dist-packages/sopel/plugins/handlers.py", line 255, in setup
    self._module.setup(bot)
  File "/usr/local/lib/python3.6/dist-packages/sopel/modules/ip.py", line 57, in setup
    bot.config.define_section('ip', GeoipSection)
  File "/usr/local/lib/python3.6/dist-packages/sopel/config/__init__.py", line 231, in define_section
    setattr(self, name, cls_(self, name, validate=validate))
  File "/usr/local/lib/python3.6/dist-packages/sopel/config/types.py", line 67, in __init__
    value)
ValueError: Missing required value for ip.GeoIP_db_path
[2020-03-05 08:26:28,009] sopel.bot            ERROR    - Error loading pointBot: invalid syntax (pointBot.py, line 52)
Traceback (most recent call last):
  File "/usr/local/lib/python3.6/dist-packages/sopel/bot.py", line 206, in setup_plugins
    plugin.load()
  File "/usr/local/lib/python3.6/dist-packages/sopel/plugins/handlers.py", line 361, in load
    self._module = self._load()
  File "/usr/local/lib/python3.6/dist-packages/sopel/plugins/handlers.py", line 344, in _load
    mod = imp.load_module(self.name, mod, self.path, description)
  File "/usr/lib/python3.6/imp.py", line 235, in load_module
    return load_source(name, filename, file)
  File "/usr/lib/python3.6/imp.py", line 172, in load_source
    module = _load(spec)
  File "<frozen importlib._bootstrap>", line 684, in _load
  File "<frozen importlib._bootstrap>", line 665, in _load_unlocked
  File "<frozen importlib._bootstrap_external>", line 674, in exec_module
  File "<frozen importlib._bootstrap_external>", line 781, in get_code
  File "<frozen importlib._bootstrap_external>", line 741, in source_to_code
  File "<frozen importlib._bootstrap>", line 219, in _call_with_frames_removed
  File "/home/jlogerqu/git/irc/sopel/plugins/pointBot.py", line 52
    except Exception, e:
                    ^
SyntaxError: invalid syntax
[2020-03-05 08:26:34,285] sopel.irc            ERROR    - ERROR received from server: Closing link: (sopel@jlogerqubox.adtran.com) [Quit: Closing]
[2020-03-05 08:27:26,642] sopel.bot            ERROR    - Error in ip setup: Missing required value for ip.GeoIP_db_path
Traceback (most recent call last):
  File "/usr/local/lib/python3.6/dist-packages/sopel/config/types.py", line 57, in __init__
    getattr(self, value)
  File "/usr/local/lib/python3.6/dist-packages/sopel/config/types.py", line 512, in __get__
    this_section = getattr(main_config, instance._section_name)
  File "/usr/local/lib/python3.6/dist-packages/sopel/config/__init__.py", line 292, in __getattr__
    section = self.ConfigSection(name, items, self)  # Return a section
  File "/usr/local/lib/python3.6/dist-packages/sopel/config/__init__.py", line 248, in __init__
    value = item[1].strip()
AttributeError: 'NoneType' object has no attribute 'strip'

During handling of the above exception, another exception occurred:

Traceback (most recent call last):
  File "/usr/local/lib/python3.6/dist-packages/sopel/bot.py", line 213, in setup_plugins
    plugin.setup(self)
  File "/usr/local/lib/python3.6/dist-packages/sopel/plugins/handlers.py", line 255, in setup
    self._module.setup(bot)
  File "/usr/local/lib/python3.6/dist-packages/sopel/modules/ip.py", line 57, in setup
    bot.config.define_section('ip', GeoipSection)
  File "/usr/local/lib/python3.6/dist-packages/sopel/config/__init__.py", line 231, in define_section
    setattr(self, name, cls_(self, name, validate=validate))
  File "/usr/local/lib/python3.6/dist-packages/sopel/config/types.py", line 67, in __init__
    value)
ValueError: Missing required value for ip.GeoIP_db_path
[2020-03-05 08:27:26,666] sopel.bot            ERROR    - Error loading pointBot: name 'prExpr' is not defined
Traceback (most recent call last):
  File "/usr/local/lib/python3.6/dist-packages/sopel/bot.py", line 206, in setup_plugins
    plugin.load()
  File "/usr/local/lib/python3.6/dist-packages/sopel/plugins/handlers.py", line 361, in load
    self._module = self._load()
  File "/usr/local/lib/python3.6/dist-packages/sopel/plugins/handlers.py", line 344, in _load
    mod = imp.load_module(self.name, mod, self.path, description)
  File "/usr/lib/python3.6/imp.py", line 235, in load_module
    return load_source(name, filename, file)
  File "/usr/lib/python3.6/imp.py", line 172, in load_source
    module = _load(spec)
  File "<frozen importlib._bootstrap>", line 684, in _load
  File "<frozen importlib._bootstrap>", line 665, in _load_unlocked
  File "<frozen importlib._bootstrap_external>", line 678, in exec_module
  File "<frozen importlib._bootstrap>", line 219, in _call_with_frames_removed
  File "/home/jlogerqu/git/irc/sopel/plugins/pointBot.py", line 32, in <module>
    @sopel.module.rule(prExpr)
NameError: name 'prExpr' is not defined
[2020-03-05 08:27:40,258] sopel.irc            ERROR    - ERROR received from server: Closing link: (sopel@jlogerqubox.adtran.com) [Quit: Closing]
[2020-03-05 08:28:25,631] sopel.bot            ERROR    - Error loading pointBot: name 'prExpr' is not defined
Traceback (most recent call last):
  File "/usr/local/lib/python3.6/dist-packages/sopel/bot.py", line 206, in setup_plugins
    plugin.load()
  File "/usr/local/lib/python3.6/dist-packages/sopel/plugins/handlers.py", line 361, in load
    self._module = self._load()
  File "/usr/local/lib/python3.6/dist-packages/sopel/plugins/handlers.py", line 344, in _load
    mod = imp.load_module(self.name, mod, self.path, description)
  File "/usr/lib/python3.6/imp.py", line 235, in load_module
    return load_source(name, filename, file)
  File "/usr/lib/python3.6/imp.py", line 172, in load_source
    module = _load(spec)
  File "<frozen importlib._bootstrap>", line 684, in _load
  File "<frozen importlib._bootstrap>", line 665, in _load_unlocked
  File "<frozen importlib._bootstrap_external>", line 678, in exec_module
  File "<frozen importlib._bootstrap>", line 219, in _call_with_frames_removed
  File "/home/jlogerqu/git/irc/sopel/plugins/pointBot.py", line 32, in <module>
    @sopel.module.rule(prExpr)
NameError: name 'prExpr' is not defined
[2020-03-05 08:28:30,960] sopel.irc            ERROR    - ERROR received from server: Closing link: (sopel@jlogerqubox.adtran.com) [Quit: Closing]
[2020-03-05 08:37:25,004] sopel.irc            ERROR    - ERROR received from server: Closing link: (sopel@jlogerqubox.adtran.com) [Quit: Closing]
[2020-03-05 09:37:32,325] sopel.bot            ERROR    - Error loading pointBot: [Errno 2] Cannot create database file. No such directory: "". Check that configuration setting core.db_filename is valid: 'default.db'
Traceback (most recent call last):
  File "/usr/local/lib/python3.6/dist-packages/sopel/bot.py", line 206, in setup_plugins
    plugin.load()
  File "/usr/local/lib/python3.6/dist-packages/sopel/plugins/handlers.py", line 361, in load
    self._module = self._load()
  File "/usr/local/lib/python3.6/dist-packages/sopel/plugins/handlers.py", line 344, in _load
    mod = imp.load_module(self.name, mod, self.path, description)
  File "/usr/lib/python3.6/imp.py", line 235, in load_module
    return load_source(name, filename, file)
  File "/usr/lib/python3.6/imp.py", line 172, in load_source
    module = _load(spec)
  File "<frozen importlib._bootstrap>", line 684, in _load
  File "<frozen importlib._bootstrap>", line 665, in _load_unlocked
  File "<frozen importlib._bootstrap_external>", line 678, in exec_module
  File "<frozen importlib._bootstrap>", line 219, in _call_with_frames_removed
  File "/home/jlogerqu/git/irc/sopel/plugins/pointBot.py", line 4, in <module>
    database = db.SopelDB(setting)
  File "/usr/local/lib/python3.6/dist-packages/sopel/db.py", line 133, in __init__
    path
FileNotFoundError: [Errno 2] Cannot create database file. No such directory: "". Check that configuration setting core.db_filename is valid: 'default.db'
[2020-03-05 09:37:58,391] sopel.irc            ERROR    - ERROR received from server: Closing link: (sopel@jlogerqubox.adtran.com) [Quit: Closing]
[2020-03-05 09:45:29,895] sopel.bot            ERROR    - Error loading pointBot: Missing required value for core.owner
Traceback (most recent call last):
  File "/usr/local/lib/python3.6/dist-packages/sopel/config/types.py", line 57, in __init__
    getattr(self, value)
  File "/usr/local/lib/python3.6/dist-packages/sopel/config/types.py", line 168, in __get__
    instance._section_name, self.name
AttributeError: Missing required value for core.owner

During handling of the above exception, another exception occurred:

Traceback (most recent call last):
  File "/usr/local/lib/python3.6/dist-packages/sopel/bot.py", line 206, in setup_plugins
    plugin.load()
  File "/usr/local/lib/python3.6/dist-packages/sopel/plugins/handlers.py", line 361, in load
    self._module = self._load()
  File "/usr/local/lib/python3.6/dist-packages/sopel/plugins/handlers.py", line 344, in _load
    mod = imp.load_module(self.name, mod, self.path, description)
  File "/usr/lib/python3.6/imp.py", line 235, in load_module
    return load_source(name, filename, file)
  File "/usr/lib/python3.6/imp.py", line 172, in load_source
    module = _load(spec)
  File "<frozen importlib._bootstrap>", line 684, in _load
  File "<frozen importlib._bootstrap>", line 665, in _load_unlocked
  File "<frozen importlib._bootstrap_external>", line 678, in exec_module
  File "<frozen importlib._bootstrap>", line 219, in _call_with_frames_removed
  File "/home/jlogerqu/git/irc/sopel/plugins/pointBot.py", line 5, in <module>
    setting = config.Config('~/.sopel/point.cfg')
  File "/usr/local/lib/python3.6/dist-packages/sopel/config/__init__.py", line 142, in __init__
    validate=validate)
  File "/usr/local/lib/python3.6/dist-packages/sopel/config/__init__.py", line 231, in define_section
    setattr(self, name, cls_(self, name, validate=validate))
  File "/usr/local/lib/python3.6/dist-packages/sopel/config/types.py", line 67, in __init__
    value)
ValueError: Missing required value for core.owner
[2020-03-05 09:47:47,095] sopel.irc            ERROR    - ERROR received from server: Closing link: (sopel@jlogerqubox.adtran.com) [Quit: Closing]
[2020-03-05 09:47:50,196] sopel.bot            ERROR    - Error loading pointBot: Missing required value for core.owner
Traceback (most recent call last):
  File "/usr/local/lib/python3.6/dist-packages/sopel/config/types.py", line 57, in __init__
    getattr(self, value)
  File "/usr/local/lib/python3.6/dist-packages/sopel/config/types.py", line 168, in __get__
    instance._section_name, self.name
AttributeError: Missing required value for core.owner

During handling of the above exception, another exception occurred:

Traceback (most recent call last):
  File "/usr/local/lib/python3.6/dist-packages/sopel/bot.py", line 206, in setup_plugins
    plugin.load()
  File "/usr/local/lib/python3.6/dist-packages/sopel/plugins/handlers.py", line 361, in load
    self._module = self._load()
  File "/usr/local/lib/python3.6/dist-packages/sopel/plugins/handlers.py", line 344, in _load
    mod = imp.load_module(self.name, mod, self.path, description)
  File "/usr/lib/python3.6/imp.py", line 235, in load_module
    return load_source(name, filename, file)
  File "/usr/lib/python3.6/imp.py", line 172, in load_source
    module = _load(spec)
  File "<frozen importlib._bootstrap>", line 684, in _load
  File "<frozen importlib._bootstrap>", line 665, in _load_unlocked
  File "<frozen importlib._bootstrap_external>", line 678, in exec_module
  File "<frozen importlib._bootstrap>", line 219, in _call_with_frames_removed
  File "/home/jlogerqu/git/irc/sopel/plugins/pointBot.py", line 5, in <module>
    setting = config.Config(os.getcwd() + "default.cfg")
  File "/usr/local/lib/python3.6/dist-packages/sopel/config/__init__.py", line 142, in __init__
    validate=validate)
  File "/usr/local/lib/python3.6/dist-packages/sopel/config/__init__.py", line 231, in define_section
    setattr(self, name, cls_(self, name, validate=validate))
  File "/usr/local/lib/python3.6/dist-packages/sopel/config/types.py", line 67, in __init__
    value)
ValueError: Missing required value for core.owner
[2020-03-05 09:50:29,574] sopel.irc            ERROR    - ERROR received from server: Closing link: (sopel@jlogerqubox.adtran.com) [Quit: Closing]
[2020-03-05 09:50:31,777] sopel.bot            ERROR    - Error loading pointBot: can't assign to operator (pointBot.py, line 4)
Traceback (most recent call last):
  File "/usr/local/lib/python3.6/dist-packages/sopel/bot.py", line 206, in setup_plugins
    plugin.load()
  File "/usr/local/lib/python3.6/dist-packages/sopel/plugins/handlers.py", line 361, in load
    self._module = self._load()
  File "/usr/local/lib/python3.6/dist-packages/sopel/plugins/handlers.py", line 344, in _load
    mod = imp.load_module(self.name, mod, self.path, description)
  File "/usr/lib/python3.6/imp.py", line 235, in load_module
    return load_source(name, filename, file)
  File "/usr/lib/python3.6/imp.py", line 172, in load_source
    module = _load(spec)
  File "<frozen importlib._bootstrap>", line 684, in _load
  File "<frozen importlib._bootstrap>", line 665, in _load_unlocked
  File "<frozen importlib._bootstrap_external>", line 674, in exec_module
  File "<frozen importlib._bootstrap_external>", line 781, in get_code
  File "<frozen importlib._bootstrap_external>", line 741, in source_to_code
  File "<frozen importlib._bootstrap>", line 219, in _call_with_frames_removed
  File "/home/jlogerqu/git/irc/sopel/plugins/pointBot.py", line 4
    with cfgFile as os.getcwd() + "default.cfg":
        ^
SyntaxError: can't assign to operator
[2020-03-05 09:51:22,394] sopel.irc            ERROR    - ERROR received from server: Closing link: (sopel@jlogerqubox.adtran.com) [Quit: Closing]
[2020-03-05 09:51:25,865] sopel.bot            ERROR    - Error loading pointBot: __enter__
Traceback (most recent call last):
  File "/usr/local/lib/python3.6/dist-packages/sopel/bot.py", line 206, in setup_plugins
    plugin.load()
  File "/usr/local/lib/python3.6/dist-packages/sopel/plugins/handlers.py", line 361, in load
    self._module = self._load()
  File "/usr/local/lib/python3.6/dist-packages/sopel/plugins/handlers.py", line 344, in _load
    mod = imp.load_module(self.name, mod, self.path, description)
  File "/usr/lib/python3.6/imp.py", line 235, in load_module
    return load_source(name, filename, file)
  File "/usr/lib/python3.6/imp.py", line 172, in load_source
    module = _load(spec)
  File "<frozen importlib._bootstrap>", line 684, in _load
  File "<frozen importlib._bootstrap>", line 665, in _load_unlocked
  File "<frozen importlib._bootstrap_external>", line 678, in exec_module
  File "<frozen importlib._bootstrap>", line 219, in _call_with_frames_removed
  File "/home/jlogerqu/git/irc/sopel/plugins/pointBot.py", line 4, in <module>
    with os.getcwd() + "default.cfg" as cfgFile:
AttributeError: __enter__
[2020-03-05 09:52:08,855] sopel.irc            ERROR    - ERROR received from server: Closing link: (sopel@jlogerqubox.adtran.com) [Quit: Closing]
[2020-03-05 09:52:13,523] sopel.bot            ERROR    - Error loading pointBot: __enter__
Traceback (most recent call last):
  File "/usr/local/lib/python3.6/dist-packages/sopel/bot.py", line 206, in setup_plugins
    plugin.load()
  File "/usr/local/lib/python3.6/dist-packages/sopel/plugins/handlers.py", line 361, in load
    self._module = self._load()
  File "/usr/local/lib/python3.6/dist-packages/sopel/plugins/handlers.py", line 344, in _load
    mod = imp.load_module(self.name, mod, self.path, description)
  File "/usr/lib/python3.6/imp.py", line 235, in load_module
    return load_source(name, filename, file)
  File "/usr/lib/python3.6/imp.py", line 172, in load_source
    module = _load(spec)
  File "<frozen importlib._bootstrap>", line 684, in _load
  File "<frozen importlib._bootstrap>", line 665, in _load_unlocked
  File "<frozen importlib._bootstrap_external>", line 678, in exec_module
  File "<frozen importlib._bootstrap>", line 219, in _call_with_frames_removed
  File "/home/jlogerqu/git/irc/sopel/plugins/pointBot.py", line 4, in <module>
    with (os.getcwd() + "default.cfg") as cfgFile:
AttributeError: __enter__
[2020-03-05 09:52:53,253] sopel.irc            ERROR    - ERROR received from server: Closing link: (sopel@jlogerqubox.adtran.com) [Quit: Closing]
[2020-03-05 09:52:58,352] sopel.bot            ERROR    - Error loading pointBot: [Errno 2] No such file or directory: '/home/jlogerqu/git/irc/sopeldefault.cfg'
Traceback (most recent call last):
  File "/usr/local/lib/python3.6/dist-packages/sopel/bot.py", line 206, in setup_plugins
    plugin.load()
  File "/usr/local/lib/python3.6/dist-packages/sopel/plugins/handlers.py", line 361, in load
    self._module = self._load()
  File "/usr/local/lib/python3.6/dist-packages/sopel/plugins/handlers.py", line 344, in _load
    mod = imp.load_module(self.name, mod, self.path, description)
  File "/usr/lib/python3.6/imp.py", line 235, in load_module
    return load_source(name, filename, file)
  File "/usr/lib/python3.6/imp.py", line 172, in load_source
    module = _load(spec)
  File "<frozen importlib._bootstrap>", line 684, in _load
  File "<frozen importlib._bootstrap>", line 665, in _load_unlocked
  File "<frozen importlib._bootstrap_external>", line 678, in exec_module
  File "<frozen importlib._bootstrap>", line 219, in _call_with_frames_removed
  File "/home/jlogerqu/git/irc/sopel/plugins/pointBot.py", line 5, in <module>
    print(open(cfgFile, "r").read())
FileNotFoundError: [Errno 2] No such file or directory: '/home/jlogerqu/git/irc/sopeldefault.cfg'
[2020-03-05 09:53:14,373] sopel.irc            ERROR    - ERROR received from server: Closing link: (sopel@jlogerqubox.adtran.com) [Quit: Closing]
[2020-03-05 09:53:18,118] sopel.bot            ERROR    - Error loading pointBot: module 'sopel.module' has no attribute 'nickname_command'
Traceback (most recent call last):
  File "/usr/local/lib/python3.6/dist-packages/sopel/bot.py", line 206, in setup_plugins
    plugin.load()
  File "/usr/local/lib/python3.6/dist-packages/sopel/plugins/handlers.py", line 361, in load
    self._module = self._load()
  File "/usr/local/lib/python3.6/dist-packages/sopel/plugins/handlers.py", line 344, in _load
    mod = imp.load_module(self.name, mod, self.path, description)
  File "/usr/lib/python3.6/imp.py", line 235, in load_module
    return load_source(name, filename, file)
  File "/usr/lib/python3.6/imp.py", line 172, in load_source
    module = _load(spec)
  File "<frozen importlib._bootstrap>", line 684, in _load
  File "<frozen importlib._bootstrap>", line 665, in _load_unlocked
  File "<frozen importlib._bootstrap_external>", line 678, in exec_module
  File "<frozen importlib._bootstrap>", line 219, in _call_with_frames_removed
  File "/home/jlogerqu/git/irc/sopel/plugins/pointBot.py", line 58, in <module>
    @module.nickname_command(r'help')
AttributeError: module 'sopel.module' has no attribute 'nickname_command'
[2020-03-05 09:56:08,774] sopel.irc            ERROR    - ERROR received from server: Closing link: (sopel@jlogerqubox.adtran.com) [Quit: Closing]
[2020-03-05 09:56:20,249] sopel.bot            ERROR    - Error loading pointBot: module 'sopel.module' has no attribute 'nickname_command'
Traceback (most recent call last):
  File "/home/jlogerqu/.virtualenvs/sopel/lib/python3.6/site-packages/sopel/bot.py", line 206, in setup_plugins
    plugin.load()
  File "/home/jlogerqu/.virtualenvs/sopel/lib/python3.6/site-packages/sopel/plugins/handlers.py", line 361, in load
    self._module = self._load()
  File "/home/jlogerqu/.virtualenvs/sopel/lib/python3.6/site-packages/sopel/plugins/handlers.py", line 344, in _load
    mod = imp.load_module(self.name, mod, self.path, description)
  File "/home/jlogerqu/.virtualenvs/sopel/lib/python3.6/imp.py", line 235, in load_module
    return load_source(name, filename, file)
  File "/home/jlogerqu/.virtualenvs/sopel/lib/python3.6/imp.py", line 172, in load_source
    module = _load(spec)
  File "<frozen importlib._bootstrap>", line 684, in _load
  File "<frozen importlib._bootstrap>", line 665, in _load_unlocked
  File "<frozen importlib._bootstrap_external>", line 678, in exec_module
  File "<frozen importlib._bootstrap>", line 219, in _call_with_frames_removed
  File "/home/jlogerqu/git/irc/sopel/plugins/pointBot.py", line 58, in <module>
    @module.nickname_command(r'help')
AttributeError: module 'sopel.module' has no attribute 'nickname_command'
[2020-03-05 09:56:26,374] sopel.irc            ERROR    - ERROR received from server: Closing link: (sopel@jlogerqubox.adtran.com) [Quit: Closing]
[2020-03-05 09:56:49,567] sopel.bot            ERROR    - Error loading pointBot: module 'sopel.module' has no attribute 'nickname_command'
Traceback (most recent call last):
  File "/home/jlogerqu/.virtualenvs/sopel/lib/python3.6/site-packages/sopel/bot.py", line 206, in setup_plugins
    plugin.load()
  File "/home/jlogerqu/.virtualenvs/sopel/lib/python3.6/site-packages/sopel/plugins/handlers.py", line 361, in load
    self._module = self._load()
  File "/home/jlogerqu/.virtualenvs/sopel/lib/python3.6/site-packages/sopel/plugins/handlers.py", line 344, in _load
    mod = imp.load_module(self.name, mod, self.path, description)
  File "/home/jlogerqu/.virtualenvs/sopel/lib/python3.6/imp.py", line 235, in load_module
    return load_source(name, filename, file)
  File "/home/jlogerqu/.virtualenvs/sopel/lib/python3.6/imp.py", line 172, in load_source
    module = _load(spec)
  File "<frozen importlib._bootstrap>", line 684, in _load
  File "<frozen importlib._bootstrap>", line 665, in _load_unlocked
  File "<frozen importlib._bootstrap_external>", line 678, in exec_module
  File "<frozen importlib._bootstrap>", line 219, in _call_with_frames_removed
  File "/home/jlogerqu/git/irc/sopel/plugins/pointBot.py", line 58, in <module>
    @module.nickname_command(r'help')
AttributeError: module 'sopel.module' has no attribute 'nickname_command'
[2020-03-05 10:01:48,949] sopel.irc            ERROR    - ERROR received from server: Closing link: (sopel@jlogerqubox.adtran.com) [Quit: Closing]
[2020-03-05 10:03:46,901] sopel.bot            ERROR    - Error loading pointBot: module 'sopel.module' has no attribute 'nickname_command'
Traceback (most recent call last):
  File "/home/jlogerqu/.virtualenvs/sopel/lib/python3.6/site-packages/sopel/bot.py", line 206, in setup_plugins
    plugin.load()
  File "/home/jlogerqu/.virtualenvs/sopel/lib/python3.6/site-packages/sopel/plugins/handlers.py", line 361, in load
    self._module = self._load()
  File "/home/jlogerqu/.virtualenvs/sopel/lib/python3.6/site-packages/sopel/plugins/handlers.py", line 344, in _load
    mod = imp.load_module(self.name, mod, self.path, description)
  File "/home/jlogerqu/.virtualenvs/sopel/lib/python3.6/imp.py", line 235, in load_module
    return load_source(name, filename, file)
  File "/home/jlogerqu/.virtualenvs/sopel/lib/python3.6/imp.py", line 172, in load_source
    module = _load(spec)
  File "<frozen importlib._bootstrap>", line 684, in _load
  File "<frozen importlib._bootstrap>", line 665, in _load_unlocked
  File "<frozen importlib._bootstrap_external>", line 678, in exec_module
  File "<frozen importlib._bootstrap>", line 219, in _call_with_frames_removed
  File "/home/jlogerqu/git/irc/sopel/plugins/pointBot.py", line 51, in <module>
    @module.nickname_command(r'help')
AttributeError: module 'sopel.module' has no attribute 'nickname_command'
[2020-03-05 10:03:53,510] sopel.irc            ERROR    - ERROR received from server: Closing link: (sopel@jlogerqubox.adtran.com) [Quit: Closing]
[2020-03-05 10:05:41,492] sopel.irc            ERROR    - ERROR received from server: Closing link: (sopel@jlogerqubox.adtran.com) [Quit: Closing]
[2020-03-05 10:11:55,038] sopel.bot            ERROR    - Unexpected error (displayPoints() missing 1 required positional argument: 'bot') from JSON at 2020-03-05 10:11:55.038079. Message was: point, points
Traceback (most recent call last):
  File "/home/jlogerqu/.virtualenvs/sopel/lib/python3.6/site-packages/sopel/bot.py", line 590, in call
    exit_code = func(sopel, trigger)
  File "/home/jlogerqu/git/irc/sopel/plugins/pointBot.py", line 69, in points
    displayPoints()
TypeError: displayPoints() missing 1 required positional argument: 'bot'
[2020-03-05 10:12:19,605] sopel.irc            ERROR    - ERROR received from server: Closing link: (sopel@jlogerqubox.adtran.com) [Quit: Closing]
[2020-03-05 10:24:39,651] sopel.irc            ERROR    - ERROR received from server: Closing link: (sopel@jlogerqubox.adtran.com) [Quit: Closing]
[2020-03-05 12:34:25,016] sopel.irc            ERROR    - ERROR received from server: Closing link: (sopel@jlogerqubox.adtran.com) [Quit: Closing]
[2020-03-05 12:37:38,727] sopel.irc            ERROR    - ERROR received from server: Closing link: (sopel@jlogerqubox.adtran.com) [Quit: Closing]
[2020-03-05 12:37:58,957] sopel.bot            ERROR    - Unexpected error (name 'users' is not defined) from JSON at 2020-03-05 12:37:58.957684. Message was: point, points
Traceback (most recent call last):
  File "/home/jlogerqu/.virtualenvs/sopel/lib/python3.6/site-packages/sopel/bot.py", line 590, in call
    exit_code = func(sopel, trigger)
  File "/home/jlogerqu/git/irc/sopel/plugins/pointBot.py", line 73, in points
    displayPoints(bot.user, bot.db)
  File "/home/jlogerqu/git/irc/sopel/plugins/pointBot.py", line 41, in displayPoints
    for user in users:
NameError: name 'users' is not defined
[2020-03-05 12:38:09,822] sopel.irc            ERROR    - ERROR received from server: Closing link: (sopel@jlogerqubox.adtran.com) [Quit: Closing]
[2020-03-05 12:38:44,983] sopel.irc            ERROR    - ERROR received from server: Closing link: (sopel@jlogerqubox.adtran.com) [Quit: Closing]
[2020-03-05 12:42:30,247] sopel.irc            ERROR    - ERROR received from server: Closing link: (sopel@jlogerqubox.adtran.com) [Quit: Closing]
[2020-03-05 12:47:35,114] sopel.tools.jobs     ERROR    - Error while processing job: local variable 'gameRunning' referenced before assignment
[2020-03-05 12:47:35,115] sopel.bot            ERROR    - Unexpected error (local variable 'gameRunning' referenced before assignment)
Traceback (most recent call last):
  File "/home/jlogerqu/.virtualenvs/sopel/lib/python3.6/site-packages/sopel/tools/jobs.py", line 118, in _call
    job.func(self.manager)
  File "/home/jlogerqu/git/irc/sopel/plugins/pointBot.py", line 84, in save
    if gameRunning and not workhour:
UnboundLocalError: local variable 'gameRunning' referenced before assignment
[2020-03-05 12:48:11,749] sopel.irc            ERROR    - ERROR received from server: Closing link: (sopel@jlogerqubox.adtran.com) [Quit: Closing]
[2020-03-05 12:55:42,729] sopel.bot            ERROR    - Error loading pointBot: invalid syntax (pointBot.py, line 110)
Traceback (most recent call last):
  File "/home/jlogerqu/.virtualenvs/sopel/lib/python3.6/site-packages/sopel/bot.py", line 206, in setup_plugins
    plugin.load()
  File "/home/jlogerqu/.virtualenvs/sopel/lib/python3.6/site-packages/sopel/plugins/handlers.py", line 361, in load
    self._module = self._load()
  File "/home/jlogerqu/.virtualenvs/sopel/lib/python3.6/site-packages/sopel/plugins/handlers.py", line 344, in _load
    mod = imp.load_module(self.name, mod, self.path, description)
  File "/home/jlogerqu/.virtualenvs/sopel/lib/python3.6/imp.py", line 235, in load_module
    return load_source(name, filename, file)
  File "/home/jlogerqu/.virtualenvs/sopel/lib/python3.6/imp.py", line 172, in load_source
    module = _load(spec)
  File "<frozen importlib._bootstrap>", line 684, in _load
  File "<frozen importlib._bootstrap>", line 665, in _load_unlocked
  File "<frozen importlib._bootstrap_external>", line 674, in exec_module
  File "<frozen importlib._bootstrap_external>", line 781, in get_code
  File "<frozen importlib._bootstrap_external>", line 741, in source_to_code
  File "<frozen importlib._bootstrap>", line 219, in _call_with_frames_removed
  File "/home/jlogerqu/git/irc/sopel/plugins/pointBot.py", line 110
    else
       ^
SyntaxError: invalid syntax
[2020-03-05 12:55:44,934] sopel.irc            ERROR    - ERROR received from server: Closing link: (sopel@jlogerqubox.adtran.com) [Quit: Closing]
[2020-03-05 12:56:04,503] sopel.bot            ERROR    - Unexpected error ('Sopel' object has no attribute 'sb') from JSON at 2020-03-05 12:56:04.503307. Message was: point, setpts JSON 10
Traceback (most recent call last):
  File "/home/jlogerqu/.virtualenvs/sopel/lib/python3.6/site-packages/sopel/bot.py", line 590, in call
    exit_code = func(sopel, trigger)
  File "/home/jlogerqu/.virtualenvs/sopel/lib/python3.6/site-packages/sopel/module.py", line 622, in guarded
    return function(bot, trigger, *args, **kwargs)
  File "/home/jlogerqu/git/irc/sopel/plugins/pointBot.py", line 109, in setptscommand
    setpts(bot.sb, user, args[1])
  File "/home/jlogerqu/.virtualenvs/sopel/lib/python3.6/site-packages/sopel/bot.py", line 1053, in __getattr__
    return getattr(self._bot, attr)
AttributeError: 'Sopel' object has no attribute 'sb'
[2020-03-05 12:56:18,873] sopel.irc            ERROR    - ERROR received from server: Closing link: (sopel@jlogerqubox.adtran.com) [Quit: Closing]
[2020-03-05 12:59:38,870] sopel.irc            ERROR    - ERROR received from server: Closing link: (sopel@jlogerqubox.adtran.com) [Quit: Closing]
[2020-03-05 13:00:44,549] sopel.irc            ERROR    - ERROR received from server: Closing link: (sopel@jlogerqubox.adtran.com) [Quit: Closing]
[2020-03-05 13:01:20,197] sopel.irc            ERROR    - ERROR received from server: Closing link: (sopel@jlogerqubox.adtran.com) [Quit: Closing]
[2020-03-05 13:03:50,645] sopel.irc            ERROR    - ERROR received from server: Closing link: (sopel@jlogerqubox.adtran.com) [Quit: Closing]
[2020-03-05 13:15:19,494] sopel.bot            ERROR    - Unexpected error (name 'getGameRunning' is not defined) from JSON at 2020-03-05 13:15:19.493956. Message was: +10 JSON hi
Traceback (most recent call last):
  File "/home/jlogerqu/.virtualenvs/sopel/lib/python3.6/site-packages/sopel/bot.py", line 590, in call
    exit_code = func(sopel, trigger)
  File "/home/jlogerqu/git/irc/sopel/plugins/pointBot.py", line 46, in addGPoints
    gameRunning = getGameRunning(bot.db, trigger.sender)
NameError: name 'getGameRunning' is not defined
[2020-03-05 13:15:49,541] sopel.irc            ERROR    - ERROR received from server: Closing link: (sopel@jlogerqubox.adtran.com) [Quit: Closing]
[2020-03-05 13:15:54,321] sopel.bot            ERROR    - Unexpected error (invalid literal for int() with base 10: '+') from JSON at 2020-03-05 13:15:54.321245. Message was: +10 JSON hi
Traceback (most recent call last):
  File "/home/jlogerqu/.virtualenvs/sopel/lib/python3.6/site-packages/sopel/bot.py", line 590, in call
    exit_code = func(sopel, trigger)
  File "/home/jlogerqu/git/irc/sopel/plugins/pointBot.py", line 49, in addGPoints
    amount = int(trigger.group(1))
ValueError: invalid literal for int() with base 10: '+'
[2020-03-05 13:16:38,773] sopel.irc            ERROR    - ERROR received from server: Closing link: (sopel@jlogerqubox.adtran.com) [Quit: Closing]
[2020-03-05 13:16:42,645] sopel.bot            ERROR    - Unexpected error (no such group) from JSON at 2020-03-05 13:16:42.645050. Message was: +10 JSON hi
Traceback (most recent call last):
  File "/home/jlogerqu/.virtualenvs/sopel/lib/python3.6/site-packages/sopel/bot.py", line 590, in call
    exit_code = func(sopel, trigger)
  File "/home/jlogerqu/git/irc/sopel/plugins/pointBot.py", line 50, in addGPoints
    user = trigger.group(4)
IndexError: no such group
[2020-03-05 13:19:15,384] sopel.irc            ERROR    - ERROR received from server: Closing link: (sopel@jlogerqubox.adtran.com) [Quit: Closing]
[2020-03-05 13:19:21,347] sopel.bot            ERROR    - Unexpected error (no such group) from JSON at 2020-03-05 13:19:21.347391. Message was: +10 JSON hi
Traceback (most recent call last):
  File "/home/jlogerqu/.virtualenvs/sopel/lib/python3.6/site-packages/sopel/bot.py", line 590, in call
    exit_code = func(sopel, trigger)
  File "/home/jlogerqu/git/irc/sopel/plugins/pointBot.py", line 51, in addGPoints
    user = trigger.group(4)
IndexError: no such group
[2020-03-05 13:21:05,049] sopel.irc            ERROR    - ERROR received from server: Closing link: (sopel@jlogerqubox.adtran.com) [Quit: Closing]
[2020-03-05 13:21:11,215] sopel.bot            ERROR    - Unexpected error (tuple index out of range) from JSON at 2020-03-05 13:21:11.215124. Message was: +10 JSON hi
Traceback (most recent call last):
  File "/home/jlogerqu/.virtualenvs/sopel/lib/python3.6/site-packages/sopel/bot.py", line 590, in call
    exit_code = func(sopel, trigger)
  File "/home/jlogerqu/git/irc/sopel/plugins/pointBot.py", line 54, in addGPoints
    user = groups[3]
IndexError: tuple index out of range
[2020-03-05 13:21:34,931] sopel.irc            ERROR    - ERROR received from server: Closing link: (sopel@jlogerqubox.adtran.com) [Quit: Closing]
[2020-03-05 13:21:40,841] sopel.bot            ERROR    - Unexpected error (unsupported operand type(s) for +: 'int' and 'str') from JSON at 2020-03-05 13:21:40.841098. Message was: +10 JSON hi
Traceback (most recent call last):
  File "/home/jlogerqu/.virtualenvs/sopel/lib/python3.6/site-packages/sopel/bot.py", line 590, in call
    exit_code = func(sopel, trigger)
  File "/home/jlogerqu/git/irc/sopel/plugins/pointBot.py", line 57, in addGPoints
    addpts(bot.db, user, amount)
  File "/home/jlogerqu/git/irc/sopel/plugins/pointBot.py", line 41, in addpts
    db.set_nick_value(user, "pts", cpts+pts)
TypeError: unsupported operand type(s) for +: 'int' and 'str'
[2020-03-05 13:22:23,603] sopel.irc            ERROR    - ERROR received from server: Closing link: (sopel@jlogerqubox.adtran.com) [Quit: Closing]
[2020-03-05 13:23:02,244] sopel.irc            ERROR    - ERROR received from server: Closing link: (sopel@jlogerqubox.adtran.com) [Quit: Closing]
[2020-03-05 13:25:30,803] sopel.irc            ERROR    - ERROR received from server: Closing link: (sopel@jlogerqubox.adtran.com) [Quit: Closing]
[2020-03-05 13:25:36,144] sopel.bot            ERROR    - Unexpected error ('Identifier' object has no attribute 'nick') from JSON at 2020-03-05 13:25:36.144193. Message was: +10 JSON hi
Traceback (most recent call last):
  File "/home/jlogerqu/.virtualenvs/sopel/lib/python3.6/site-packages/sopel/bot.py", line 590, in call
    exit_code = func(sopel, trigger)
  File "/home/jlogerqu/git/irc/sopel/plugins/pointBot.py", line 57, in addGPoints
    if user != buser.nick:
AttributeError: 'Identifier' object has no attribute 'nick'
[2020-03-05 13:30:23,572] sopel.irc            ERROR    - ERROR received from server: Closing link: (sopel@jlogerqubox.adtran.com) [Quit: Closing]
[2020-03-05 13:30:28,737] sopel.bot            ERROR    - Unexpected error ('Identifier' object has no attribute 'nick') from JSON at 2020-03-05 13:30:28.737380. Message was: +10 JSON hi
Traceback (most recent call last):
  File "/home/jlogerqu/.virtualenvs/sopel/lib/python3.6/site-packages/sopel/bot.py", line 590, in call
    exit_code = func(sopel, trigger)
  File "/home/jlogerqu/git/irc/sopel/plugins/pointBot.py", line 57, in addGPoints
    if user != buser.nick:
AttributeError: 'Identifier' object has no attribute 'nick'
[2020-03-05 13:31:03,075] sopel.irc            ERROR    - ERROR received from server: Closing link: (sopel@jlogerqubox.adtran.com) [Quit: Closing]
[2020-03-05 13:31:51,011] sopel.irc            ERROR    - ERROR received from server: Closing link: (sopel@jlogerqubox.adtran.com) [Quit: Closing]
[2020-03-05 13:32:17,011] sopel.irc            ERROR    - ERROR received from server: Closing link: (sopel@jlogerqubox.adtran.com) [Quit: Closing]
[2020-03-05 13:34:28,892] sopel.irc            ERROR    - ERROR received from server: Closing link: (sopel@jlogerqubox.adtran.com) [Quit: Closing]
[2020-03-05 13:35:02,476] sopel.irc            ERROR    - ERROR received from server: Closing link: (sopel@jlogerqubox.adtran.com) [Quit: Closing]
[2020-03-05 13:35:37,273] sopel.irc            ERROR    - ERROR received from server: Closing link: (sopel@jlogerqubox.adtran.com) [Quit: Closing]
[2020-03-05 13:35:42,763] sopel.bot            ERROR    - Unexpected error ('JSON') from JSON at 2020-03-05 13:35:42.763560. Message was: +10 JSON hi
Traceback (most recent call last):
  File "/home/jlogerqu/.virtualenvs/sopel/lib/python3.6/site-packages/sopel/bot.py", line 590, in call
    exit_code = func(sopel, trigger)
  File "/home/jlogerqu/git/irc/sopel/plugins/pointBot.py", line 56, in addGPoints
    print(bot.users[user])
KeyError: 'JSON'
[2020-03-05 13:35:49,796] sopel.irc            ERROR    - ERROR received from server: Closing link: (sopel@jlogerqubox.adtran.com) [Quit: Closing]
[2020-03-05 13:44:26,554] sopel.irc            ERROR    - ERROR received from server: Closing link: (sopel@jlogerqubox.adtran.com) [Quit: Closing]
[2020-03-05 13:45:41,480] sopel.irc            ERROR    - ERROR received from server: Closing link: (sopel@jlogerqubox.adtran.com) [Quit: Closing]
[2020-03-05 13:50:44,067] sopel.tools.jobs     ERROR    - Error while processing job: local variable 'gameRunning' referenced before assignment
[2020-03-05 13:50:44,068] sopel.bot            ERROR    - Unexpected error (local variable 'gameRunning' referenced before assignment)
Traceback (most recent call last):
  File "/home/jlogerqu/.virtualenvs/sopel/lib/python3.6/site-packages/sopel/tools/jobs.py", line 118, in _call
    job.func(self.manager)
  File "/home/jlogerqu/git/irc/sopel/plugins/pointBot.py", line 91, in save
    if gameRunning and not workhour:
UnboundLocalError: local variable 'gameRunning' referenced before assignment
[2020-03-05 13:55:44,127] sopel.tools.jobs     ERROR    - Error while processing job: local variable 'gameRunning' referenced before assignment
[2020-03-05 13:55:44,128] sopel.bot            ERROR    - Unexpected error (local variable 'gameRunning' referenced before assignment)
Traceback (most recent call last):
  File "/home/jlogerqu/.virtualenvs/sopel/lib/python3.6/site-packages/sopel/tools/jobs.py", line 118, in _call
    job.func(self.manager)
  File "/home/jlogerqu/git/irc/sopel/plugins/pointBot.py", line 91, in save
    if gameRunning and not workhour:
UnboundLocalError: local variable 'gameRunning' referenced before assignment
[2020-03-05 14:00:44,070] sopel.tools.jobs     ERROR    - Error while processing job: local variable 'gameRunning' referenced before assignment
[2020-03-05 14:00:44,071] sopel.bot            ERROR    - Unexpected error (local variable 'gameRunning' referenced before assignment)
Traceback (most recent call last):
  File "/home/jlogerqu/.virtualenvs/sopel/lib/python3.6/site-packages/sopel/tools/jobs.py", line 118, in _call
    job.func(self.manager)
  File "/home/jlogerqu/git/irc/sopel/plugins/pointBot.py", line 91, in save
    if gameRunning and not workhour:
UnboundLocalError: local variable 'gameRunning' referenced before assignment
[2020-03-05 14:05:44,279] sopel.tools.jobs     ERROR    - Error while processing job: local variable 'gameRunning' referenced before assignment
[2020-03-05 14:05:44,279] sopel.bot            ERROR    - Unexpected error (local variable 'gameRunning' referenced before assignment)
Traceback (most recent call last):
  File "/home/jlogerqu/.virtualenvs/sopel/lib/python3.6/site-packages/sopel/tools/jobs.py", line 118, in _call
    job.func(self.manager)
  File "/home/jlogerqu/git/irc/sopel/plugins/pointBot.py", line 91, in save
    if gameRunning and not workhour:
UnboundLocalError: local variable 'gameRunning' referenced before assignment
[2020-03-05 14:10:44,598] sopel.tools.jobs     ERROR    - Error while processing job: local variable 'gameRunning' referenced before assignment
[2020-03-05 14:10:44,599] sopel.bot            ERROR    - Unexpected error (local variable 'gameRunning' referenced before assignment)
Traceback (most recent call last):
  File "/home/jlogerqu/.virtualenvs/sopel/lib/python3.6/site-packages/sopel/tools/jobs.py", line 118, in _call
    job.func(self.manager)
  File "/home/jlogerqu/git/irc/sopel/plugins/pointBot.py", line 91, in save
    if gameRunning and not workhour:
UnboundLocalError: local variable 'gameRunning' referenced before assignment
[2020-03-05 14:15:44,806] sopel.tools.jobs     ERROR    - Error while processing job: local variable 'gameRunning' referenced before assignment
[2020-03-05 14:15:44,807] sopel.bot            ERROR    - Unexpected error (local variable 'gameRunning' referenced before assignment)
Traceback (most recent call last):
  File "/home/jlogerqu/.virtualenvs/sopel/lib/python3.6/site-packages/sopel/tools/jobs.py", line 118, in _call
    job.func(self.manager)
  File "/home/jlogerqu/git/irc/sopel/plugins/pointBot.py", line 91, in save
    if gameRunning and not workhour:
UnboundLocalError: local variable 'gameRunning' referenced before assignment
[2020-03-05 14:20:44,061] sopel.tools.jobs     ERROR    - Error while processing job: local variable 'gameRunning' referenced before assignment
[2020-03-05 14:20:44,062] sopel.bot            ERROR    - Unexpected error (local variable 'gameRunning' referenced before assignment)
Traceback (most recent call last):
  File "/home/jlogerqu/.virtualenvs/sopel/lib/python3.6/site-packages/sopel/tools/jobs.py", line 118, in _call
    job.func(self.manager)
  File "/home/jlogerqu/git/irc/sopel/plugins/pointBot.py", line 91, in save
    if gameRunning and not workhour:
UnboundLocalError: local variable 'gameRunning' referenced before assignment
[2020-03-05 14:25:44,761] sopel.tools.jobs     ERROR    - Error while processing job: local variable 'gameRunning' referenced before assignment
[2020-03-05 14:25:44,762] sopel.bot            ERROR    - Unexpected error (local variable 'gameRunning' referenced before assignment)
Traceback (most recent call last):
  File "/home/jlogerqu/.virtualenvs/sopel/lib/python3.6/site-packages/sopel/tools/jobs.py", line 118, in _call
    job.func(self.manager)
  File "/home/jlogerqu/git/irc/sopel/plugins/pointBot.py", line 91, in save
    if gameRunning and not workhour:
UnboundLocalError: local variable 'gameRunning' referenced before assignment
[2020-03-05 14:30:44,407] sopel.tools.jobs     ERROR    - Error while processing job: local variable 'gameRunning' referenced before assignment
[2020-03-05 14:30:44,407] sopel.bot            ERROR    - Unexpected error (local variable 'gameRunning' referenced before assignment)
Traceback (most recent call last):
  File "/home/jlogerqu/.virtualenvs/sopel/lib/python3.6/site-packages/sopel/tools/jobs.py", line 118, in _call
    job.func(self.manager)
  File "/home/jlogerqu/git/irc/sopel/plugins/pointBot.py", line 91, in save
    if gameRunning and not workhour:
UnboundLocalError: local variable 'gameRunning' referenced before assignment
[2020-03-05 14:35:44,843] sopel.tools.jobs     ERROR    - Error while processing job: local variable 'gameRunning' referenced before assignment
[2020-03-05 14:35:44,843] sopel.bot            ERROR    - Unexpected error (local variable 'gameRunning' referenced before assignment)
Traceback (most recent call last):
  File "/home/jlogerqu/.virtualenvs/sopel/lib/python3.6/site-packages/sopel/tools/jobs.py", line 118, in _call
    job.func(self.manager)
  File "/home/jlogerqu/git/irc/sopel/plugins/pointBot.py", line 91, in save
    if gameRunning and not workhour:
UnboundLocalError: local variable 'gameRunning' referenced before assignment
[2020-03-05 14:40:44,228] sopel.tools.jobs     ERROR    - Error while processing job: local variable 'gameRunning' referenced before assignment
[2020-03-05 14:40:44,229] sopel.bot            ERROR    - Unexpected error (local variable 'gameRunning' referenced before assignment)
Traceback (most recent call last):
  File "/home/jlogerqu/.virtualenvs/sopel/lib/python3.6/site-packages/sopel/tools/jobs.py", line 118, in _call
    job.func(self.manager)
  File "/home/jlogerqu/git/irc/sopel/plugins/pointBot.py", line 91, in save
    if gameRunning and not workhour:
UnboundLocalError: local variable 'gameRunning' referenced before assignment
[2020-03-05 14:45:44,574] sopel.tools.jobs     ERROR    - Error while processing job: local variable 'gameRunning' referenced before assignment
[2020-03-05 14:45:44,575] sopel.bot            ERROR    - Unexpected error (local variable 'gameRunning' referenced before assignment)
Traceback (most recent call last):
  File "/home/jlogerqu/.virtualenvs/sopel/lib/python3.6/site-packages/sopel/tools/jobs.py", line 118, in _call
    job.func(self.manager)
  File "/home/jlogerqu/git/irc/sopel/plugins/pointBot.py", line 91, in save
    @module.interval(300)
UnboundLocalError: local variable 'gameRunning' referenced before assignment
[2020-03-05 14:50:44,074] sopel.tools.jobs     ERROR    - Error while processing job: local variable 'gameRunning' referenced before assignment
[2020-03-05 14:50:44,093] sopel.bot            ERROR    - Unexpected error (local variable 'gameRunning' referenced before assignment)
Traceback (most recent call last):
  File "/home/jlogerqu/.virtualenvs/sopel/lib/python3.6/site-packages/sopel/tools/jobs.py", line 118, in _call
    job.func(self.manager)
  File "/home/jlogerqu/git/irc/sopel/plugins/pointBot.py", line 91, in save
    @module.interval(300)
UnboundLocalError: local variable 'gameRunning' referenced before assignment
[2020-03-05 14:55:44,837] sopel.tools.jobs     ERROR    - Error while processing job: local variable 'gameRunning' referenced before assignment
[2020-03-05 14:55:44,838] sopel.bot            ERROR    - Unexpected error (local variable 'gameRunning' referenced before assignment)
Traceback (most recent call last):
  File "/home/jlogerqu/.virtualenvs/sopel/lib/python3.6/site-packages/sopel/tools/jobs.py", line 118, in _call
    job.func(self.manager)
  File "/home/jlogerqu/git/irc/sopel/plugins/pointBot.py", line 91, in save
    @module.interval(300)
UnboundLocalError: local variable 'gameRunning' referenced before assignment
[2020-03-05 15:00:44,175] sopel.tools.jobs     ERROR    - Error while processing job: local variable 'gameRunning' referenced before assignment
[2020-03-05 15:00:44,176] sopel.bot            ERROR    - Unexpected error (local variable 'gameRunning' referenced before assignment)
Traceback (most recent call last):
  File "/home/jlogerqu/.virtualenvs/sopel/lib/python3.6/site-packages/sopel/tools/jobs.py", line 118, in _call
    job.func(self.manager)
  File "/home/jlogerqu/git/irc/sopel/plugins/pointBot.py", line 91, in save
    ptsstring = displayPoints(bot.db, bot.users)
UnboundLocalError: local variable 'gameRunning' referenced before assignment
[2020-03-05 15:05:44,201] sopel.tools.jobs     ERROR    - Error while processing job: local variable 'gameRunning' referenced before assignment
[2020-03-05 15:05:44,202] sopel.bot            ERROR    - Unexpected error (local variable 'gameRunning' referenced before assignment)
Traceback (most recent call last):
  File "/home/jlogerqu/.virtualenvs/sopel/lib/python3.6/site-packages/sopel/tools/jobs.py", line 118, in _call
    job.func(self.manager)
  File "/home/jlogerqu/git/irc/sopel/plugins/pointBot.py", line 91, in save
    ptsstring = displayPoints(bot.db, bot.users)
UnboundLocalError: local variable 'gameRunning' referenced before assignment
[2020-03-05 15:10:43,991] sopel.tools.jobs     ERROR    - Error while processing job: local variable 'gameRunning' referenced before assignment
[2020-03-05 15:10:43,992] sopel.bot            ERROR    - Unexpected error (local variable 'gameRunning' referenced before assignment)
Traceback (most recent call last):
  File "/home/jlogerqu/.virtualenvs/sopel/lib/python3.6/site-packages/sopel/tools/jobs.py", line 118, in _call
    job.func(self.manager)
  File "/home/jlogerqu/git/irc/sopel/plugins/pointBot.py", line 91, in save
    ptsstring = displayPoints(bot.db, bot.users)
UnboundLocalError: local variable 'gameRunning' referenced before assignment
[2020-03-05 15:15:44,832] sopel.tools.jobs     ERROR    - Error while processing job: local variable 'gameRunning' referenced before assignment
[2020-03-05 15:15:44,833] sopel.bot            ERROR    - Unexpected error (local variable 'gameRunning' referenced before assignment)
Traceback (most recent call last):
  File "/home/jlogerqu/.virtualenvs/sopel/lib/python3.6/site-packages/sopel/tools/jobs.py", line 118, in _call
    job.func(self.manager)
  File "/home/jlogerqu/git/irc/sopel/plugins/pointBot.py", line 91, in save
    ptsstring = displayPoints(bot.db, bot.users)
UnboundLocalError: local variable 'gameRunning' referenced before assignment
[2020-03-05 15:20:44,776] sopel.tools.jobs     ERROR    - Error while processing job: local variable 'gameRunning' referenced before assignment
[2020-03-05 15:20:44,777] sopel.bot            ERROR    - Unexpected error (local variable 'gameRunning' referenced before assignment)
Traceback (most recent call last):
  File "/home/jlogerqu/.virtualenvs/sopel/lib/python3.6/site-packages/sopel/tools/jobs.py", line 118, in _call
    job.func(self.manager)
  File "/home/jlogerqu/git/irc/sopel/plugins/pointBot.py", line 91, in save
    ptsstring = displayPoints(bot.db, bot.users)
UnboundLocalError: local variable 'gameRunning' referenced before assignment
[2020-03-05 15:25:43,937] sopel.tools.jobs     ERROR    - Error while processing job: local variable 'gameRunning' referenced before assignment
[2020-03-05 15:25:43,937] sopel.bot            ERROR    - Unexpected error (local variable 'gameRunning' referenced before assignment)
Traceback (most recent call last):
  File "/home/jlogerqu/.virtualenvs/sopel/lib/python3.6/site-packages/sopel/tools/jobs.py", line 118, in _call
    job.func(self.manager)
  File "/home/jlogerqu/git/irc/sopel/plugins/pointBot.py", line 91, in save
    ptsstring = displayPoints(bot.db, bot.users)
UnboundLocalError: local variable 'gameRunning' referenced before assignment
[2020-03-05 15:30:44,297] sopel.tools.jobs     ERROR    - Error while processing job: local variable 'gameRunning' referenced before assignment
[2020-03-05 15:30:44,298] sopel.bot            ERROR    - Unexpected error (local variable 'gameRunning' referenced before assignment)
Traceback (most recent call last):
  File "/home/jlogerqu/.virtualenvs/sopel/lib/python3.6/site-packages/sopel/tools/jobs.py", line 118, in _call
    job.func(self.manager)
  File "/home/jlogerqu/git/irc/sopel/plugins/pointBot.py", line 91, in save
UnboundLocalError: local variable 'gameRunning' referenced before assignment
[2020-03-05 15:30:50,365] sopel.irc            ERROR    - ERROR received from server: Closing link: (sopel@jlogerqubox.adtran.com) [Quit: Closing]
[2020-03-05 15:52:08,875] sopel.bot            ERROR    - Error loading pointBot: module 'sopel.module' has no attribute 'requie_admin'
Traceback (most recent call last):
  File "/home/jlogerqu/.virtualenvs/sopel/lib/python3.6/site-packages/sopel/bot.py", line 206, in setup_plugins
    plugin.load()
  File "/home/jlogerqu/.virtualenvs/sopel/lib/python3.6/site-packages/sopel/plugins/handlers.py", line 361, in load
    self._module = self._load()
  File "/home/jlogerqu/.virtualenvs/sopel/lib/python3.6/site-packages/sopel/plugins/handlers.py", line 344, in _load
    mod = imp.load_module(self.name, mod, self.path, description)
  File "/home/jlogerqu/.virtualenvs/sopel/lib/python3.6/imp.py", line 235, in load_module
    return load_source(name, filename, file)
  File "/home/jlogerqu/.virtualenvs/sopel/lib/python3.6/imp.py", line 172, in load_source
    module = _load(spec)
  File "<frozen importlib._bootstrap>", line 684, in _load
  File "<frozen importlib._bootstrap>", line 665, in _load_unlocked
  File "<frozen importlib._bootstrap_external>", line 678, in exec_module
  File "<frozen importlib._bootstrap>", line 219, in _call_with_frames_removed
  File "/home/jlogerqu/git/irc/sopel/plugins/pointBot.py", line 156, in <module>
    @module.requie_admin()
AttributeError: module 'sopel.module' has no attribute 'requie_admin'
[2020-03-05 15:52:10,748] sopel.irc            ERROR    - ERROR received from server: Closing link: (sopel@jlogerqubox.adtran.com) [Quit: Closing]
[2020-03-05 15:53:01,826] sopel.bot            ERROR    - Unexpected error (name 'getUserFromUser' is not defined) from JSON at 2020-03-05 15:53:01.826632. Message was: +10 JSON jfdlsa
Traceback (most recent call last):
  File "/home/jlogerqu/.virtualenvs/sopel/lib/python3.6/site-packages/sopel/bot.py", line 590, in call
    exit_code = func(sopel, trigger)
  File "/home/jlogerqu/git/irc/sopel/plugins/pointBot.py", line 84, in addGPoints
    triggeruser = getUserFromUser(trigger.nick, bot.users)
NameError: name 'getUserFromUser' is not defined
[2020-03-05 15:53:26,587] sopel.irc            ERROR    - ERROR received from server: Closing link: (sopel@jlogerqubox.adtran.com) [Quit: Closing]
[2020-03-05 15:53:33,478] sopel.bot            ERROR    - Unexpected error ('User' object has no attribute 'lower') from JSON at 2020-03-05 15:53:33.478618. Message was: +10 JSON jfdlsa
Traceback (most recent call last):
  File "/home/jlogerqu/.virtualenvs/sopel/lib/python3.6/site-packages/sopel/bot.py", line 590, in call
    exit_code = func(sopel, trigger)
  File "/home/jlogerqu/git/irc/sopel/plugins/pointBot.py", line 95, in addGPoints
    gpts = getgpts(bot.db, triggeruser)
  File "/home/jlogerqu/git/irc/sopel/plugins/pointBot.py", line 45, in getgpts
    return db.set_nick_value(user, "gpts", 0)
  File "/home/jlogerqu/.virtualenvs/sopel/lib/python3.6/site-packages/sopel/db.py", line 374, in set_nick_value
    nick = Identifier(nick)
  File "/home/jlogerqu/.virtualenvs/sopel/lib/python3.6/site-packages/sopel/tools/__init__.py", line 399, in __new__
    s._lowered = Identifier._lower(identifier)
  File "/home/jlogerqu/.virtualenvs/sopel/lib/python3.6/site-packages/sopel/tools/__init__.py", line 423, in _lower
    low = identifier.lower().replace('[', '{').replace(']', '}')
AttributeError: 'User' object has no attribute 'lower'
[2020-03-05 15:54:26,109] sopel.irc            ERROR    - ERROR received from server: Closing link: (sopel@jlogerqubox.adtran.com) [Quit: Closing]
[2020-03-05 15:54:32,324] sopel.bot            ERROR    - Unexpected error ('User' object has no attribute 'lower') from JSON at 2020-03-05 15:54:32.324612. Message was: +10 JSON jfdlsa
Traceback (most recent call last):
  File "/home/jlogerqu/.virtualenvs/sopel/lib/python3.6/site-packages/sopel/bot.py", line 590, in call
    exit_code = func(sopel, trigger)
  File "/home/jlogerqu/git/irc/sopel/plugins/pointBot.py", line 95, in addGPoints
    gpts = getgpts(bot.db, triggeruser)
  File "/home/jlogerqu/git/irc/sopel/plugins/pointBot.py", line 45, in getgpts
    return db.set_nick_value(user, "gpts", 0)
  File "/home/jlogerqu/.virtualenvs/sopel/lib/python3.6/site-packages/sopel/db.py", line 374, in set_nick_value
    nick = Identifier(nick)
  File "/home/jlogerqu/.virtualenvs/sopel/lib/python3.6/site-packages/sopel/tools/__init__.py", line 399, in __new__
    s._lowered = Identifier._lower(identifier)
  File "/home/jlogerqu/.virtualenvs/sopel/lib/python3.6/site-packages/sopel/tools/__init__.py", line 423, in _lower
    low = identifier.lower().replace('[', '{').replace(']', '}')
AttributeError: 'User' object has no attribute 'lower'
[2020-03-05 15:55:51,468] sopel.irc            ERROR    - ERROR received from server: Closing link: (sopel@jlogerqubox.adtran.com) [Quit: Closing]
[2020-03-05 15:55:57,589] sopel.bot            ERROR    - Unexpected error ('>' not supported between instances of 'int' and 'NoneType') from JSON at 2020-03-05 15:55:57.589131. Message was: +10 JSON jfdlsa
Traceback (most recent call last):
  File "/home/jlogerqu/.virtualenvs/sopel/lib/python3.6/site-packages/sopel/bot.py", line 590, in call
    exit_code = func(sopel, trigger)
  File "/home/jlogerqu/git/irc/sopel/plugins/pointBot.py", line 95, in addGPoints
    if abs(amount) > gpts:
TypeError: '>' not supported between instances of 'int' and 'NoneType'
[2020-03-05 15:56:42,778] sopel.irc            ERROR    - ERROR received from server: Closing link: (sopel@jlogerqubox.adtran.com) [Quit: Closing]
[2020-03-05 16:08:18,155] sopel.irc            ERROR    - ERROR received from server: Closing link: (sopel@jlogerqubox.adtran.com) [Quit: Closing]
[2020-03-05 16:08:54,267] sopel.bot            ERROR    - Unexpected error (name 'pts' is not defined) from JSON at 2020-03-05 16:08:54.267665. Message was: point, setgpts JSON 10
Traceback (most recent call last):
  File "/home/jlogerqu/.virtualenvs/sopel/lib/python3.6/site-packages/sopel/bot.py", line 590, in call
    exit_code = func(sopel, trigger)
  File "/home/jlogerqu/.virtualenvs/sopel/lib/python3.6/site-packages/sopel/module.py", line 622, in guarded
    return function(bot, trigger, *args, **kwargs)
  File "/home/jlogerqu/git/irc/sopel/plugins/pointBot.py", line 169, in setgptscommand
    setgpts(bot.db, args[0], args[1])
  File "/home/jlogerqu/git/irc/sopel/plugins/pointBot.py", line 49, in setgpts
    db.set_nick_value(user, "gpts", pts)
NameError: name 'pts' is not defined
[2020-03-05 16:10:04,938] sopel.irc            ERROR    - ERROR received from server: Closing link: (sopel@jlogerqubox.adtran.com) [Quit: Closing]
[2020-03-05 16:10:34,660] sopel.bot            ERROR    - Unexpected error (name 'pts' is not defined) from JSON at 2020-03-05 16:10:34.660327. Message was: +10 JSON jfdlsa
Traceback (most recent call last):
  File "/home/jlogerqu/.virtualenvs/sopel/lib/python3.6/site-packages/sopel/bot.py", line 590, in call
    exit_code = func(sopel, trigger)
  File "/home/jlogerqu/git/irc/sopel/plugins/pointBot.py", line 100, in addGPoints
    addpts(bot.db, user, amount)
  File "/home/jlogerqu/git/irc/sopel/plugins/pointBot.py", line 43, in addpts
    setpts(db, user, pts+cpts)
NameError: name 'pts' is not defined
[2020-03-05 16:11:02,490] sopel.irc            ERROR    - ERROR received from server: Closing link: (sopel@jlogerqubox.adtran.com) [Quit: Closing]
[2020-03-05 16:11:10,514] sopel.bot            ERROR    - Unexpected error (unsupported operand type(s) for +: 'int' and 'NoneType') from JSON at 2020-03-05 16:11:10.514012. Message was: +10 JSON jfdlsa
Traceback (most recent call last):
  File "/home/jlogerqu/.virtualenvs/sopel/lib/python3.6/site-packages/sopel/bot.py", line 590, in call
    exit_code = func(sopel, trigger)
  File "/home/jlogerqu/git/irc/sopel/plugins/pointBot.py", line 100, in addGPoints
    addpts(bot.db, user, amount)
  File "/home/jlogerqu/git/irc/sopel/plugins/pointBot.py", line 43, in addpts
    setpts(db, user, pts+cpts)
TypeError: unsupported operand type(s) for +: 'int' and 'NoneType'
[2020-03-05 16:11:33,642] sopel.irc            ERROR    - ERROR received from server: Closing link: (sopel@jlogerqubox.adtran.com) [Quit: Closing]
[2020-03-05 16:16:56,639] sopel.irc            ERROR    - ERROR received from server: Closing link: (sopel@jlogerqubox.adtran.com) [Quit: Closing]
[2020-03-05 16:22:54,012] sopel.tools.jobs     ERROR    - Error while processing job: 'str' object has no attribute 'match'
[2020-03-05 16:22:54,013] sopel.bot            ERROR    - Unexpected error ('str' object has no attribute 'match')
Traceback (most recent call last):
  File "/home/jlogerqu/.virtualenvs/sopel/lib/python3.6/site-packages/sopel/tools/jobs.py", line 118, in _call
    job.func(self.manager)
  File "/home/jlogerqu/git/irc/sopel/plugins/pointBot.py", line 84, in save
    "You get 10 points to give away every day, and these points are refreshed every morning at 8 AM. " +
AttributeError: 'str' object has no attribute 'match'
[2020-03-05 16:27:54,135] sopel.tools.jobs     ERROR    - Error while processing job: 'str' object has no attribute 'match'
[2020-03-05 16:27:54,135] sopel.bot            ERROR    - Unexpected error ('str' object has no attribute 'match')
Traceback (most recent call last):
  File "/home/jlogerqu/.virtualenvs/sopel/lib/python3.6/site-packages/sopel/tools/jobs.py", line 118, in _call
    job.func(self.manager)
  File "/home/jlogerqu/git/irc/sopel/plugins/pointBot.py", line 84, in save
    "You get 10 points to give away every day, and these points are refreshed every morning at 8 AM. " +
AttributeError: 'str' object has no attribute 'match'
[2020-03-05 16:32:54,073] sopel.tools.jobs     ERROR    - Error while processing job: 'str' object has no attribute 'match'
[2020-03-05 16:32:54,073] sopel.bot            ERROR    - Unexpected error ('str' object has no attribute 'match')
Traceback (most recent call last):
  File "/home/jlogerqu/.virtualenvs/sopel/lib/python3.6/site-packages/sopel/tools/jobs.py", line 118, in _call
    job.func(self.manager)
  File "/home/jlogerqu/git/irc/sopel/plugins/pointBot.py", line 84, in save
    "You get 10 points to give away every day, and these points are refreshed every morning at 8 AM. " +
AttributeError: 'str' object has no attribute 'match'
[2020-03-05 16:37:54,719] sopel.tools.jobs     ERROR    - Error while processing job: 'str' object has no attribute 'match'
[2020-03-05 16:37:54,719] sopel.bot            ERROR    - Unexpected error ('str' object has no attribute 'match')
Traceback (most recent call last):
  File "/home/jlogerqu/.virtualenvs/sopel/lib/python3.6/site-packages/sopel/tools/jobs.py", line 118, in _call
    job.func(self.manager)
  File "/home/jlogerqu/git/irc/sopel/plugins/pointBot.py", line 84, in save
    "You get 10 points to give away every day, and these points are refreshed every morning at 8 AM. " +
AttributeError: 'str' object has no attribute 'match'
[2020-03-05 16:42:54,817] sopel.tools.jobs     ERROR    - Error while processing job: 'str' object has no attribute 'match'
[2020-03-05 16:42:54,817] sopel.bot            ERROR    - Unexpected error ('str' object has no attribute 'match')
Traceback (most recent call last):
  File "/home/jlogerqu/.virtualenvs/sopel/lib/python3.6/site-packages/sopel/tools/jobs.py", line 118, in _call
    job.func(self.manager)
  File "/home/jlogerqu/git/irc/sopel/plugins/pointBot.py", line 84, in save
    "You get 10 points to give away every day, and these points are refreshed every morning at 8 AM. " +
AttributeError: 'str' object has no attribute 'match'
[2020-03-05 16:44:55,749] sopel.irc            ERROR    - ERROR received from server: Closing link: (sopel@jlogerqubox.adtran.com) [Quit: Closing]
[2020-03-05 16:45:13,190] sopel.bot            ERROR    - Unexpected error ('User' object has no attribute 'lower') from JSON at 2020-03-05 16:45:13.190244. Message was: point, setbot point true
Traceback (most recent call last):
  File "/home/jlogerqu/.virtualenvs/sopel/lib/python3.6/site-packages/sopel/bot.py", line 590, in call
    exit_code = func(sopel, trigger)
  File "/home/jlogerqu/.virtualenvs/sopel/lib/python3.6/site-packages/sopel/module.py", line 622, in guarded
    return function(bot, trigger, *args, **kwargs)
  File "/home/jlogerqu/git/irc/sopel/plugins/pointBot.py", line 165, in setbotcommand
    setUserBotStatus(bot.db, user, isbot)
  File "/home/jlogerqu/git/irc/sopel/plugins/pointBot.py", line 247, in setUserBotStatus
    db.set_nick_value(user, "bot", status)
  File "/home/jlogerqu/.virtualenvs/sopel/lib/python3.6/site-packages/sopel/db.py", line 374, in set_nick_value
    nick = Identifier(nick)
  File "/home/jlogerqu/.virtualenvs/sopel/lib/python3.6/site-packages/sopel/tools/__init__.py", line 399, in __new__
    s._lowered = Identifier._lower(identifier)
  File "/home/jlogerqu/.virtualenvs/sopel/lib/python3.6/site-packages/sopel/tools/__init__.py", line 423, in _lower
    low = identifier.lower().replace('[', '{').replace(']', '}')
AttributeError: 'User' object has no attribute 'lower'
[2020-03-05 16:47:46,900] sopel.irc            ERROR    - ERROR received from server: Closing link: (sopel@jlogerqubox.adtran.com) [Quit: Closing]
[2020-03-05 16:47:52,646] sopel.bot            ERROR    - Unexpected error ('User' object has no attribute 'lower') from JSON at 2020-03-05 16:47:52.646586. Message was: point, setbot point true
Traceback (most recent call last):
  File "/home/jlogerqu/.virtualenvs/sopel/lib/python3.6/site-packages/sopel/bot.py", line 590, in call
    exit_code = func(sopel, trigger)
  File "/home/jlogerqu/.virtualenvs/sopel/lib/python3.6/site-packages/sopel/module.py", line 622, in guarded
    return function(bot, trigger, *args, **kwargs)
  File "/home/jlogerqu/git/irc/sopel/plugins/pointBot.py", line 166, in setbotcommand
    setUserBotStatus(bot.db, user, isbot)
  File "/home/jlogerqu/git/irc/sopel/plugins/pointBot.py", line 248, in setUserBotStatus
    db.set_nick_value(user, "bot", status)
  File "/home/jlogerqu/.virtualenvs/sopel/lib/python3.6/site-packages/sopel/db.py", line 374, in set_nick_value
    nick = Identifier(nick)
  File "/home/jlogerqu/.virtualenvs/sopel/lib/python3.6/site-packages/sopel/tools/__init__.py", line 399, in __new__
    s._lowered = Identifier._lower(identifier)
  File "/home/jlogerqu/.virtualenvs/sopel/lib/python3.6/site-packages/sopel/tools/__init__.py", line 423, in _lower
    low = identifier.lower().replace('[', '{').replace(']', '}')
AttributeError: 'User' object has no attribute 'lower'
[2020-03-05 16:48:22,645] sopel.irc            ERROR    - ERROR received from server: Closing link: (sopel@jlogerqubox.adtran.com) [Quit: Closing]
[2020-03-05 16:48:27,291] sopel.bot            ERROR    - Unexpected error ('User' object has no attribute 'lower') from JSON at 2020-03-05 16:48:27.290983. Message was: point, setbot point true
Traceback (most recent call last):
  File "/home/jlogerqu/.virtualenvs/sopel/lib/python3.6/site-packages/sopel/bot.py", line 590, in call
    exit_code = func(sopel, trigger)
  File "/home/jlogerqu/.virtualenvs/sopel/lib/python3.6/site-packages/sopel/module.py", line 622, in guarded
    return function(bot, trigger, *args, **kwargs)
  File "/home/jlogerqu/git/irc/sopel/plugins/pointBot.py", line 168, in setbotcommand
    setUserBotStatus(bot.db, user, isbot)
  File "/home/jlogerqu/git/irc/sopel/plugins/pointBot.py", line 250, in setUserBotStatus
    db.set_nick_value(user, "bot", status)
  File "/home/jlogerqu/.virtualenvs/sopel/lib/python3.6/site-packages/sopel/db.py", line 374, in set_nick_value
    nick = Identifier(nick)
  File "/home/jlogerqu/.virtualenvs/sopel/lib/python3.6/site-packages/sopel/tools/__init__.py", line 399, in __new__
    s._lowered = Identifier._lower(identifier)
  File "/home/jlogerqu/.virtualenvs/sopel/lib/python3.6/site-packages/sopel/tools/__init__.py", line 423, in _lower
    low = identifier.lower().replace('[', '{').replace(']', '}')
AttributeError: 'User' object has no attribute 'lower'
[2020-03-05 16:49:21,508] sopel.irc            ERROR    - ERROR received from server: Closing link: (sopel@jlogerqubox.adtran.com) [Quit: Closing]
[2020-03-05 16:49:27,307] sopel.bot            ERROR    - Unexpected error ('User' object has no attribute 'lower') from JSON at 2020-03-05 16:49:27.306956. Message was: point, setbot point true
Traceback (most recent call last):
  File "/home/jlogerqu/.virtualenvs/sopel/lib/python3.6/site-packages/sopel/bot.py", line 590, in call
    exit_code = func(sopel, trigger)
  File "/home/jlogerqu/.virtualenvs/sopel/lib/python3.6/site-packages/sopel/module.py", line 622, in guarded
    return function(bot, trigger, *args, **kwargs)
  File "/home/jlogerqu/git/irc/sopel/plugins/pointBot.py", line 168, in setbotcommand
    setUserBotStatus(bot.db, user, isbot)
  File "/home/jlogerqu/git/irc/sopel/plugins/pointBot.py", line 250, in setUserBotStatus
    db.set_nick_value(user, "bot", status)
  File "/home/jlogerqu/.virtualenvs/sopel/lib/python3.6/site-packages/sopel/db.py", line 374, in set_nick_value
    nick = Identifier(nick)
  File "/home/jlogerqu/.virtualenvs/sopel/lib/python3.6/site-packages/sopel/tools/__init__.py", line 399, in __new__
    s._lowered = Identifier._lower(identifier)
  File "/home/jlogerqu/.virtualenvs/sopel/lib/python3.6/site-packages/sopel/tools/__init__.py", line 423, in _lower
    low = identifier.lower().replace('[', '{').replace(']', '}')
AttributeError: 'User' object has no attribute 'lower'
[2020-03-05 16:50:03,971] sopel.irc            ERROR    - ERROR received from server: Closing link: (sopel@jlogerqubox.adtran.com) [Quit: Closing]
[2020-03-05 16:54:17,140] sopel.irc            ERROR    - ERROR received from server: Closing link: (sopel@jlogerqubox.adtran.com) [Quit: Closing]
[2020-03-05 16:54:30,390] sopel.bot            ERROR    - Unexpected error (name 'getplayers' is not defined) from JSON at 2020-03-05 16:54:30.390595. Message was: point, points
Traceback (most recent call last):
  File "/home/jlogerqu/.virtualenvs/sopel/lib/python3.6/site-packages/sopel/bot.py", line 590, in call
    exit_code = func(sopel, trigger)
  File "/home/jlogerqu/git/irc/sopel/plugins/pointBot.py", line 92, in displaypoints
    players = getplayers(bot.db, bot.users)
NameError: name 'getplayers' is not defined
[2020-03-05 16:54:50,580] sopel.irc            ERROR    - ERROR received from server: Closing link: (sopel@jlogerqubox.adtran.com) [Quit: Closing]
[2020-03-05 16:55:02,230] sopel.bot            ERROR    - Unexpected error ('NoneType' object is not iterable) from JSON at 2020-03-05 16:55:02.230699. Message was: point, points
Traceback (most recent call last):
  File "/home/jlogerqu/.virtualenvs/sopel/lib/python3.6/site-packages/sopel/bot.py", line 590, in call
    exit_code = func(sopel, trigger)
  File "/home/jlogerqu/git/irc/sopel/plugins/pointBot.py", line 93, in displaypoints
    ptsstring = displayPoints(bot.db, players)
  File "/home/jlogerqu/git/irc/sopel/plugins/pointBot.py", line 200, in displayPoints
    for user in users:
TypeError: 'NoneType' object is not iterable
[2020-03-05 16:56:09,140] sopel.irc            ERROR    - ERROR received from server: Closing link: (sopel@jlogerqubox.adtran.com) [Quit: Closing]
[2020-03-05 16:56:23,858] sopel.bot            ERROR    - Unexpected error ('NoneType' object is not iterable) from JSON at 2020-03-05 16:56:23.858670. Message was: point, points
Traceback (most recent call last):
  File "/home/jlogerqu/.virtualenvs/sopel/lib/python3.6/site-packages/sopel/bot.py", line 590, in call
    exit_code = func(sopel, trigger)
  File "/home/jlogerqu/git/irc/sopel/plugins/pointBot.py", line 94, in displaypoints
    ptsstring = displayPoints(bot.db, players)
  File "/home/jlogerqu/git/irc/sopel/plugins/pointBot.py", line 201, in displayPoints
    for user in users:
TypeError: 'NoneType' object is not iterable
[2020-03-05 16:56:46,419] sopel.irc            ERROR    - ERROR received from server: Closing link: (sopel@jlogerqubox.adtran.com) [Quit: Closing]
[2020-03-05 16:56:51,150] sopel.bot            ERROR    - Unexpected error ('NoneType' object is not iterable) from JSON at 2020-03-05 16:56:51.150669. Message was: point, points
Traceback (most recent call last):
  File "/home/jlogerqu/.virtualenvs/sopel/lib/python3.6/site-packages/sopel/bot.py", line 590, in call
    exit_code = func(sopel, trigger)
  File "/home/jlogerqu/git/irc/sopel/plugins/pointBot.py", line 94, in displaypoints
    ptsstring = displayPoints(bot.db, players)
  File "/home/jlogerqu/git/irc/sopel/plugins/pointBot.py", line 201, in displayPoints
    for user in users:
TypeError: 'NoneType' object is not iterable
[2020-03-05 16:57:35,253] sopel.irc            ERROR    - ERROR received from server: Closing link: (sopel@jlogerqubox.adtran.com) [Quit: Closing]
[2020-03-05 16:57:41,442] sopel.bot            ERROR    - Unexpected error ('NoneType' object is not iterable) from JSON at 2020-03-05 16:57:41.442249. Message was: point, points
Traceback (most recent call last):
  File "/home/jlogerqu/.virtualenvs/sopel/lib/python3.6/site-packages/sopel/bot.py", line 590, in call
    exit_code = func(sopel, trigger)
  File "/home/jlogerqu/git/irc/sopel/plugins/pointBot.py", line 94, in displaypoints
    ptsstring = displayPoints(bot.db, players)
  File "/home/jlogerqu/git/irc/sopel/plugins/pointBot.py", line 201, in displayPoints
    for user in users:
TypeError: 'NoneType' object is not iterable
[2020-03-05 16:58:09,321] sopel.irc            ERROR    - ERROR received from server: Closing link: (sopel@jlogerqubox.adtran.com) [Quit: Closing]
[2020-03-05 16:59:27,859] sopel.irc            ERROR    - ERROR received from server: Closing link: (sopel@jlogerqubox.adtran.com) [Quit: Closing]
[2020-03-05 17:00:39,571] sopel.irc            ERROR    - ERROR received from server: Closing link: (sopel@jlogerqubox.adtran.com) [Quit: Closing]
[2020-03-05 17:01:33,821] sopel.irc            ERROR    - ERROR received from server: Closing link: (sopel@jlogerqubox.adtran.com) [Quit: Closing]
[2020-03-05 17:05:27,091] sopel.irc            ERROR    - ERROR received from server: Closing link: (sopel@jlogerqubox.adtran.com) [Quit: Closing]
[2020-03-05 17:05:51,667] sopel.irc            ERROR    - ERROR received from server: Closing link: (sopel@jlogerqubox.adtran.com) [Quit: Closing]
[2020-03-05 17:05:54,343] sopel.bot            ERROR    - Error loading pointBot: invalid syntax (pointBot.py, line 258)
Traceback (most recent call last):
  File "/home/jlogerqu/.virtualenvs/sopel/lib/python3.6/site-packages/sopel/bot.py", line 206, in setup_plugins
    plugin.load()
  File "/home/jlogerqu/.virtualenvs/sopel/lib/python3.6/site-packages/sopel/plugins/handlers.py", line 361, in load
    self._module = self._load()
  File "/home/jlogerqu/.virtualenvs/sopel/lib/python3.6/site-packages/sopel/plugins/handlers.py", line 344, in _load
    mod = imp.load_module(self.name, mod, self.path, description)
  File "/home/jlogerqu/.virtualenvs/sopel/lib/python3.6/imp.py", line 235, in load_module
    return load_source(name, filename, file)
  File "/home/jlogerqu/.virtualenvs/sopel/lib/python3.6/imp.py", line 172, in load_source
    module = _load(spec)
  File "<frozen importlib._bootstrap>", line 684, in _load
  File "<frozen importlib._bootstrap>", line 665, in _load_unlocked
  File "<frozen importlib._bootstrap_external>", line 674, in exec_module
  File "<frozen importlib._bootstrap_external>", line 781, in get_code
  File "<frozen importlib._bootstrap_external>", line 741, in source_to_code
  File "<frozen importlib._bootstrap>", line 219, in _call_with_frames_removed
  File "/home/jlogerqu/git/irc/sopel/plugins/pointBot.py", line 258
    isplayer =  !(getUserBotStatus(db, user) or getUserIgnoreStatus(db, user))
                ^
SyntaxError: invalid syntax
[2020-03-05 17:05:57,811] sopel.irc            ERROR    - ERROR received from server: Closing link: (sopel@jlogerqubox.adtran.com) [Quit: Closing]
